Workbook

Sheet Summary
A1: Korea Tour Comparison: 6 Packages
A2: Side-by-side summary. Every number here is linked to the detail sheets, so edits there flow through.
A5: Tour | B5: Aviatour | C5: Bayu Buana | D5: Obaja | E5: Panorama | F5: Wita | G5: Rotama
A6: The trip
A7: Departure | B7: ='Days & Flights'!B7 -> 04 Apr 2027 (also 08 Apr) | C7: ='Days & Flights'!C7 -> 05 / 06 / 07 Apr 2027 | D7: ='Days & Flights'!D7 -> 16 Mar 2027 | E7: ='Days & Flights'!E7 -> 16 Mar 2027 | F7: ='Days & Flights'!F7 -> 26 Mar (2027, presumed) | G7: ='Days & Flights'!G7 -> 11 Nov (2026)
A8: Days / hotel nights | B8: ='Days & Flights'!B9&"D / "&'Days & Flights'!B10&"N" -> 7D / 5N | C8: ='Days & Flights'!C9&"D / "&'Days & Flights'!C10&"N" -> 7D / 5N | D8: ='Days & Flights'!D9&"D / "&'Days & Flights'!D10&"N" -> 7D / 5N | E8: ='Days & Flights'!E9&"D / "&'Days & Flights'!E10&"N" -> 8D / 6N | F8: ='Days & Flights'!F9&"D / "&'Days & Flights'!F10&"N" -> 7D / 5N | G8: ='Days & Flights'!G9&"D / "&'Days & Flights'!G10&"N" -> 5D / 3N
A9: Guided touring days | B9: ='Days & Flights'!B11 -> 5 | C9: ='Days & Flights'!C11 -> 5 | D9: ='Days & Flights'!D11 -> 4 | E9: ='Days & Flights'!E11 -> 5 | F9: ='Days & Flights'!F11 -> 5 | G9: ='Days & Flights'!G11 -> 3
A10: Places | B10: Busan · Jeonju · Seoul | C10: Busan · Jinhae · Nami · Seoul | D10: Busan · Nami · Seoul | E10: Busan · Maehwa · Gurye · Jeonju · Seoul | F10: Busan · Jinhae · Seoul | G10: Seoul area only
A11: Airline | B11: ='Days & Flights'!B14 -> Singapore Airlines | C11: ='Days & Flights'!C14 -> Singapore Airlines | D11: ='Days & Flights'!D14 -> Singapore Airlines | E11: ='Days & Flights'!E14 -> Singapore Airlines | F11: ='Days & Flights'!F14 -> Singapore Airlines | G11: ='Days & Flights'!G14 -> Trinity Airways (TW, ex-T'way)
A12: Routing | B12: ='Days & Flights'!B19 -> Incheon in & out; KTX train to Busan on Day 2 | C12: ='Days & Flights'!C19 -> Open-jaw: Busan in, Incheon out | D12: ='Days & Flights'!D19 -> Open-jaw: Busan in, Incheon out | E12: ='Days & Flights'!E19 -> Open-jaw: Busan in, Incheon out | F12: ='Days & Flights'!F19 -> Open-jaw: Busan in, Incheon out; KTX Busan → Seoul | G12: ='Days & Flights'!G19 -> Direct, no transit
A13: Season | B13: ='Days & Flights'!B23 -> Cherry blossom: Seoul Yeouido near peak; Busan may be fading | C13: ='Days & Flights'!C23 -> Jinhae on 8 Apr is late in its peak window (riskier) | D13: ='Days & Flights'!D23 -> Early spring: before cherry blossom | E13: ='Days & Flights'!E23 -> Plum & sansuyu blossoms (what the tour is built for); no cherry blossom | F13: ='Days & Flights'!F23 -> Jinhae on 28 Mar sits in its usual peak window; Seoul may be early | G13: ='Days & Flights'!G23 -> Late autumn, cold; foliage likely past peak
A14: Money
A15: List price (adult twin) | B15: =Price!B7 -> 23390000 | C15: =Price!C7 -> 26888000 | D15: =Price!D7 -> 17900000 | E15: =Price!E7 -> 23190000 | F15: =Price!F7 -> 26350000 | G15: =Price!G7 -> 10290000
A16: ALL-IN PRICE PER ADULT | B16: =Price!B23 -> 26947290 | C16: =Price!C23 -> 28583768 | D16: =Price!D23 -> 19521900 | E16: =Price!E23 -> 25650090 | F16: =Price!F23 -> 28954850 | G16: =Price!G23 -> 11303190
A17: Price rank (1 = cheapest) | B17: =Price!B26 -> 4 | C17: =Price!C26 -> 5 | D17: =Price!D26 -> 2 | E17: =Price!E26 -> 3 | F17: =Price!F26 -> 6 | G17: =Price!G26 -> 1
A18: Cost per day | B18: =Price!B28 -> 3849612.9 | C18: =Price!C28 -> 4083395.4 | D18: =Price!D28 -> 2788842.9 | E18: =Price!E28 -> 3206261.2 | F18: =Price!F28 -> 4136407.1 | G18: =Price!G28 -> 2260638
A19: Single supplement | B19: =Price!B12 -> 6000000 | C19: =Price!C12 -> 7000000 | D19: =Price!D12 -> 8000000 | E19: =Price!E12 -> 8000000 | F19: =Price!F12 -> 7500000 | G19: =Price!G12 -> 3000000
A20: Comfort
A21: Hotel class | B21: =Hotels!B7 -> 3★ or equivalent | C21: =Hotels!C7 -> "Superior Class" (no stars stated) | D21: =Hotels!D7 -> 3★ | E21: =Hotels!E7 -> Not stated (named hotels) | F21: =Hotels!F7 -> 4★ | G21: =Hotels!G7 -> 3★
A22: Seoul hotel | B22: =Hotels!B10 -> 3 nights · 3★, "Seoul or nearby" | C22: =Hotels!C10 -> 3 nights · unnamed | D22: =Hotels!D10 -> 4 nights · Anyang Samwon Hotel | E22: =Hotels!E10 -> 4 nights · Baiton Dongdaemun Hotel | F22: =Hotels!F10 -> 3 nights · Migliore Hotel | G22: =Hotels!G10 -> 3 nights · Samwon Plaza Hotel
A23: Hotel ranking (1 = best) | B23: =Hotels!B13 -> 5 | C23: =Hotels!C13 -> 6 | D23: =Hotels!D13 -> 3 | E23: =Hotels!E13 -> 2 | F23: =Hotels!F13 -> 1 | G23: =Hotels!G13 -> 4
A24: Meals included | B24: =Meals!B19 -> 12 | C24: =Meals!C19 -> 10 | D24: =Meals!D19 -> 8 | E24: =Meals!E19 -> 14 | F24: =Meals!F19 -> 11 | G24: =Meals!G19 -> 3
A25: Checked baggage | B25: ='Days & Flights'!B20 -> 20 kg + 7 kg cabin | C25: ='Days & Flights'!C20 -> Not legible (free cabin suitcase gift) | D25: ='Days & Flights'!D20 -> 25 kg + 7 kg cabin | E25: ='Days & Flights'!E20 -> Not stated | F25: ='Days & Flights'!F20 -> Per airline rules | G25: ='Days & Flights'!G20 -> Per airline rules (low-cost: check)
A26: Compulsory shop stops | B26: =Terms!B8 -> 5 | C26: =Terms!C8 -> 6 | D26: =Terms!D8 -> 5 | E26: =Terms!E8 -> 4 | F26: =Terms!F8 -> 4 | G26: =Terms!G8 -> 4
A27: Sightseeing
A28: Sights & experiences | B28: =Sightseeing!B56 -> 18 | C28: =Sightseeing!C56 -> 15 | D28: =Sightseeing!D56 -> 9 | E28: =Sightseeing!E56 -> 19 | F28: =Sightseeing!F56 -> 18 | G28: =Sightseeing!G56 -> 13
A29: Subjective score (out of 5) | B29: ='Sightseeing Opinion'!B14 -> 3.8571429 | C29: ='Sightseeing Opinion'!C14 -> 3.5714286 | D29: ='Sightseeing Opinion'!D14 -> 2.1428571 | E29: ='Sightseeing Opinion'!E14 -> 4.1428571 | F29: ='Sightseeing Opinion'!F14 -> 4 | G29: ='Sightseeing Opinion'!G14 -> 2.4285714
A31: Bottom line
A32: Lowest cost | B32: Rotama (short trip) · Obaja (full-length trip)
A33: Most for the money | B33: Panorama: 8 days, 14 meals, city-centre hotels
A34: Best hotels | B34: Wita (only 4★) · Panorama (city centre + hanok night)
A35: Jinhae / Busan cherry blossom | B35: Wita (28 Mar, best timing)
A36: Seoul cherry blossom, lower price | B36: Aviatour (Yeouido, 9 Apr)
A37: Most relaxed flight home | B37: Bayu Buana (11:05 departure)
A38: Overall without cherry blossom | B38: Panorama
A40: Before booking: confirm the agents' handwritten quotes in writing; ask Aviatour for tipping, Bayu Buana for hotel names and page 3, and Wita about the Busan routing and Lotte World ticket.

Sheet Price
A1: Price
A2: Per adult, twin share, in IDR. Blue = brochure figures; black = formulas. All-in adds every compulsory extra.
A5: Tour | B5: Aviatour | C5: Bayu Buana | D5: Obaja | E5: Panorama | F5: Wita | G5: Rotama
A6: List prices (per person)
A7: Adult twin share | B7: 23390000 | C7: 26888000 | D7: 17900000 | E7: 23190000 | F7: 26350000 | G7: 10290000
A8: Child twin share | B8: 23390000 | C8: 26888000 | D8: 17900000 | E8: 23190000 | F8: 26350000 | G8: 10290000
A9: Child extra bed / triple | B9: 23390000 | C9: 26388000 | D9: 17900000 | E9: 22190000 | F9: 26350000 | G9: 10290000
A10: Child no bed | B10: 22890000 | C10: 25888000 | D10: 17500000 | E10: 21190000 | F10: 25350000 | G10: 10290000
A11: Infant | E11: 6000000
A12: Single supplement | B12: 6000000 | C12: 7000000 | D12: 8000000 | E12: 8000000 | F12: 7500000 | G12: 3000000
A13: Compulsory extras on top of the adult price
A14: Airport tax / fuel surcharge | B14: 1200000 | C14: 2300000 | D14: 0 | E14: 0 | F14: 0 | G14: 0
A15: Korea visa | B15: 1150000 | C15: 1150000 | D15: 0 | E15: 1281000 | F15: 1315000 | G15: 0
A16: Tipping quoted in USD | D16: 50 | E16: 56
A17: Tipping (IDR) | B17: =Notes!$B$7 -> 950000 | C17: 950000 | D17: =D16*Notes!$B$6 -> 825000 | E17: =E16*Notes!$B$6 -> 924000 | F17: 1000000 | G17: 900000
A18: Extra insurance charge | B18: 0 | C18: 0 | D18: 600000 | E18: 0 | F18: 0 | G18: 0
A19: PPN (VAT) rate | B19: 0.011 | C19: 0.011 | D19: =Notes!$B$8 -> 0.011 | E19: 0.011 | F19: 0.011 | G19: 0.011
A20: PPN amount | B20: =B7*B19 -> 257290 | C20: =C7*C19 -> 295768 | D20: =D7*D19 -> 196900 | E20: =E7*E19 -> 255090 | F20: =F7*F19 -> 289850 | G20: =G7*G19 -> 113190
A21: Discount | B21: 0 | C21: -3000000 | D21: 0 | E21: 0 | F21: 0 | G21: 0
A22: All-in cost per adult
A23: ALL-IN PRICE (calculated) | B23: =B7+B14+B15+B17+B18+B20+B21 -> 26947290 | C23: =C7+C14+C15+C17+C18+C20+C21 -> 28583768 | D23: =D7+D14+D15+D17+D18+D20+D21 -> 19521900 | E23: =E7+E14+E15+E17+E18+E20+E21 -> 25650090 | F23: =F7+F14+F15+F17+F18+F20+F21 -> 28954850 | G23: =G7+G14+G15+G17+G18+G20+G21 -> 11303190
A24: Agent's handwritten quote | C24: 28580718 | E24: 24726090 | F24: 28955000 | G24: 11305000
A25: Calculated minus quote | B25: =IF(B24="","",B23-B24) | C25: =IF(C24="","",C23-C24) -> 3050 | D25: =IF(D24="","",D23-D24) | E25: =IF(E24="","",E23-E24) -> 924000 | F25: =IF(F24="","",F23-F24) -> -150 | G25: =IF(G24="","",G23-G24) -> -1810
A26: Price rank (1 = cheapest) | B26: =RANK(B23,$B$23:$G$23,1) -> 4 | C26: =RANK(C23,$B$23:$G$23,1) -> 5 | D26: =RANK(D23,$B$23:$G$23,1) -> 2 | E26: =RANK(E23,$B$23:$G$23,1) -> 3 | F26: =RANK(F23,$B$23:$G$23,1) -> 6 | G26: =RANK(G23,$B$23:$G$23,1) -> 1
A27: Value for money
A28: Per day | B28: =B23/'Days & Flights'!B9 -> 3849612.9 | C28: =C23/'Days & Flights'!C9 -> 4083395.4 | D28: =D23/'Days & Flights'!D9 -> 2788842.9 | E28: =E23/'Days & Flights'!E9 -> 3206261.2 | F28: =F23/'Days & Flights'!F9 -> 4136407.1 | G28: =G23/'Days & Flights'!G9 -> 2260638
A29: Per hotel night | B29: =B23/'Days & Flights'!B10 -> 5389458 | C29: =C23/'Days & Flights'!C10 -> 5716753.6 | D29: =D23/'Days & Flights'!D10 -> 3904380 | E29: =E23/'Days & Flights'!E10 -> 4275015 | F29: =F23/'Days & Flights'!F10 -> 5790970 | G29: =G23/'Days & Flights'!G10 -> 3767730
A30: Per guided touring day | B30: =B23/'Days & Flights'!B11 -> 5389458 | C30: =C23/'Days & Flights'!C11 -> 5716753.6 | D30: =D23/'Days & Flights'!D11 -> 4880475 | E30: =E23/'Days & Flights'!E11 -> 5130018 | F30: =F23/'Days & Flights'!F11 -> 5790970 | G30: =G23/'Days & Flights'!G11 -> 3767730
A32: Rotama is a 5-day Seoul-only trip in November on a low-cost airline. Compare its price with care. USD tipping converted at the rate on the Notes sheet.

Sheet Days & Flights
A1: Days & Flights
A2: Trip length, timing in Korea and flight details for each package.
A5: Tour | B5: Aviatour | C5: Bayu Buana | D5: Obaja | E5: Panorama | F5: Wita | G5: Rotama
A6: Dates & length
A7: Departure | B7: 04 Apr 2027 (also 08 Apr) | C7: 05 / 06 / 07 Apr 2027 | D7: 16 Mar 2027 | E7: 16 Mar 2027 | F7: 26 Mar (2027, presumed) | G7: 11 Nov (2026)
A8: Dates in Korea | B8: 5 – 10 Apr | C8: 7 – 12 Apr (06 Apr dep.) | D8: 17 – 22 Mar | E8: 17 – 23 Mar | F8: 27 Mar – 1 Apr | G8: 12 – 15 Nov
A9: Total days | B9: 7 | C9: 7 | D9: 7 | E9: 8 | F9: 7 | G9: 5
A10: Hotel nights | B10: 5 | C10: 5 | D10: 5 | E10: 6 | F10: 5 | G10: 3
A11: Guided touring days | B11: 5 | C11: 5 | D11: 4 | E11: 5 | F11: 5 | G11: 3
A12: Free days (no bus / guide) | B12: 0 | C12: 0 | D12: 1 | E12: 1 | F12: 0 | G12: 0
A13: Flights
A14: Airline | B14: Singapore Airlines | C14: Singapore Airlines | D14: Singapore Airlines | E14: Singapore Airlines | F14: Singapore Airlines | G14: Trinity Airways (TW, ex-T'way)
A15: Outbound | B15: SQ965 CGK–SIN 19:20–22:05 SQ608 SIN–ICN 00:20–07:45 | C15: SQ963 CGK–SIN 18:05–20:55 SQ616 SIN–PUS 23:15–06:50 | D15: SQ965 CGK–SIN 19:20–22:05 SQ616 SIN–PUS 23:05–06:20 | E15: SQ963 CGK–SIN 18:10–20:55 SQ616 SIN–PUS 23:25–06:45 | F15: SQ963 CGK–SIN 18:10–20:55 SQ616 SIN–PUS 23:30–06:45 | G15: TW156 CGK–ICN 21:50–07:05 (direct)
A16: Return | B16: SQ607 ICN–SIN 09:00–14:20 SQ962 SIN–CGK 16:15–17:10 | C16: SQ611 ICN–SIN 11:05–16:35 SQ966 SIN–CGK 18:30–19:20 | D16: SQ607 ICN–SIN 09:00–14:20 SQ962 SIN–CGK 16:15–17:10 | E16: SQ607 ICN–SIN 08:50–14:25 SQ962 SIN–CGK 16:10–17:05 | F16: SQ607 ICN–SIN 09:00–14:20 SQ962 SIN–CGK 16:15–17:10 | G16: TW155 ICN–CGK 14:50–20:10 (direct)
A17: Arrive Korea | B17: Day 2, 07:45 · Incheon | C17: Day 2, 06:50 · Busan | D17: Day 2, 06:20 · Busan | E17: Day 2, 06:45 · Busan | F17: Day 2, 06:45 · Busan | G17: Day 2, 07:05 · Incheon
A18: Leave Korea | B18: Day 7, 09:00 · Incheon | C18: Day 7, 11:05 · Incheon | D18: Day 7, 09:00 · Incheon | E18: Day 8, 08:50 · Incheon | F18: Day 7, 09:00 · Incheon | G18: Day 5, 14:50 · Incheon
A19: Routing | B19: Incheon in & out; KTX train to Busan on Day 2 | C19: Open-jaw: Busan in, Incheon out | D19: Open-jaw: Busan in, Incheon out | E19: Open-jaw: Busan in, Incheon out | F19: Open-jaw: Busan in, Incheon out; KTX Busan → Seoul | G19: Direct, no transit
A20: Checked baggage | B20: 20 kg + 7 kg cabin | C20: Not legible (free cabin suitcase gift) | D20: 25 kg + 7 kg cabin | E20: Not stated | F20: Per airline rules | G20: Per airline rules (low-cost: check)
A21: Watch out for | B21: ~3 h KTX transfer straight after the overnight flight | C21: Most relaxed last morning (11:05) | D21: Only 1 h connection in Singapore outbound | E21: Early 08:50 departure | F21: Early 09:00 departure | G21: Low-cost carrier: meals / bags may cost extra
A22: Season
A23: Typical season at travel time | B23: Cherry blossom: Seoul Yeouido near peak; Busan may be fading | C23: Jinhae on 8 Apr is late in its peak window (riskier) | D23: Early spring: before cherry blossom | E23: Plum & sansuyu blossoms (what the tour is built for); no cherry blossom | F23: Jinhae on 28 Mar sits in its usual peak window; Seoul may be early | G23: Late autumn, cold; foliage likely past peak
A25: Every tour spends night 1 on the plane and lands early on Day 2. Bloom dates vary each year.

Sheet Hotels
A1: Hotels
A2: Where you sleep each night. Hover over a cell with a red corner for brochure notes.
A5: Tour | B5: Aviatour | C5: Bayu Buana | D5: Obaja | E5: Panorama | F5: Wita | G5: Rotama
A6: Accommodation
A7: Hotel class | B7: 3★ or equivalent | C7: "Superior Class" (no stars stated) | D7: 3★ | E7: Not stated (named hotels) | F7: 4★ | G7: 3★
A8: Busan | B8: 1 night · 3★ (unnamed) | C8: 2 nights · unnamed | D8: 1 night · Busan Tourist Hotel | E8: 1 night · Griffin Busan Hotel | F8: 2 nights · Layers Hotel Busan | G8: –
A9: Jeonju | B9: 1 night · 3★ (unnamed) | C9: – | D9: – | E9: 1 night · Nabijam Jeonju Hanok Hotel (traditional ondol room) | F9: – | G9: –
A10: Seoul area | B10: 3 nights · 3★, "Seoul or nearby" | C10: 3 nights · unnamed | D10: 4 nights · Anyang Samwon Hotel | E10: 4 nights · Baiton Dongdaemun Hotel | F10: 3 nights · Migliore Hotel | G10: 3 nights · Samwon Plaza Hotel
A11: Location | B11: Seoul hotel may be outside the city | C11: Unknown: ask the agent | D11: Anyang, a satellite city south of Seoul | E11: Seoul city centre ("Hotel City Centre") | F11: A Hotel Migliore operates in Myeongdong, central Seoul (confirm) | G11: Gyeonggi, outside Seoul
A12: Watch out for | B12: No hotel names given | C12: No hotel names or stars legible | D12: No hotel porter; commute on free day | E12: Hanok night = floor bedding | F12: Most expensive tour | G12: Commute into Seoul each day
A13: Hotel ranking (1 = best) | B13: 5 | C13: 6 | D13: 3 | E13: 2 | F13: 1 | G13: 4
A15: All hotels are "or equivalent" (atau setaraf) and may be swapped for similar hotels if fully booked.

Sheet Meals
A1: Meals
A2: B = breakfast · L = lunch · D = dinner · – = no meal. Totals are counted by formula from the daily grid.
A5: Tour | B5: Aviatour | C5: Bayu Buana | D5: Obaja | E5: Panorama | F5: Wita | G5: Rotama
A6: Day by day
A7: Day 1 | B7: – | C7: – | D7: – | E7: – | F7: – | G7: –
A8: Day 2 | B8: L · D | C8: L | D8: L | E8: L · D | F8: L · D | G8: –
A9: Day 3 | B9: B · L · D | C9: B · L | D9: B · L | E9: B · L · D | F9: B · L · D | G9: B
A10: Day 4 | B10: B · L | C10: B · L | D10: B · L | E10: B · L · D | F10: B · L | G10: B
A11: Day 5 | B11: B · L | C11: B · L | D11: B | E11: B · L | F11: B · L | G11: B
A12: Day 6 | B12: B · L | C12: B · L | D12: B | E12: B · L | F12: B
A13: Day 7 | B13: B | C13: B | D13: B | E13: B | F13: B
A14: Day 8 | E14: B
A15: Totals
A16: Breakfasts | B16: =COUNTIF(B7:B14,"*B*") -> 5 | C16: =COUNTIF(C7:C14,"*B*") -> 5 | D16: =COUNTIF(D7:D14,"*B*") -> 5 | E16: =COUNTIF(E7:E14,"*B*") -> 6 | F16: =COUNTIF(F7:F14,"*B*") -> 5 | G16: =COUNTIF(G7:G14,"*B*") -> 3
A17: Lunches | B17: =COUNTIF(B7:B14,"*L*") -> 5 | C17: =COUNTIF(C7:C14,"*L*") -> 5 | D17: =COUNTIF(D7:D14,"*L*") -> 3 | E17: =COUNTIF(E7:E14,"*L*") -> 5 | F17: =COUNTIF(F7:F14,"*L*") -> 4 | G17: =COUNTIF(G7:G14,"*L*") -> 0
A18: Dinners | B18: =COUNTIF(B7:B14,"*D*") -> 2 | C18: =COUNTIF(C7:C14,"*D*") -> 0 | D18: =COUNTIF(D7:D14,"*D*") -> 0 | E18: =COUNTIF(E7:E14,"*D*") -> 3 | F18: =COUNTIF(F7:F14,"*D*") -> 2 | G18: =COUNTIF(G7:G14,"*D*") -> 0
A19: TOTAL MEALS | B19: =SUM(B16:B18) -> 12 | C19: =SUM(C16:C18) -> 10 | D19: =SUM(D16:D18) -> 8 | E19: =SUM(E16:E18) -> 14 | F19: =SUM(F16:F18) -> 11 | G19: =SUM(G16:G18) -> 3
A20: Meals you pay for yourself (approx.) | B20: ='Days & Flights'!B10*3-B19+3 -> 6 | C20: ='Days & Flights'!C10*3-C19+3 -> 8 | D20: ='Days & Flights'!D10*3-D19+3 -> 10 | E20: ='Days & Flights'!E10*3-E19+3 -> 7 | F20: ='Days & Flights'!F10*3-F19+3 -> 7 | G20: ='Days & Flights'!G10*3-G19+3 -> 9
A21: Food extras | B21: Gimbap making · BIFF Street food | C21: Shabu-shabu buffet · ramyeon making at Han River · kimchi making | D21: Kimbap making · 1 bottle of water per day | E21: Samgyetang at Tosokchon · kimbap making · strawberry picking · water | F21: Kimbap making · Gwangjang & Jagalchi markets | G21: Kimchi making

Sheet Terms
A1: Terms & Shopping
A2: Compulsory shop stops, fines, deposits and what's thrown in.
A5: Tour | B5: Aviatour | C5: Bayu Buana | D5: Obaja | E5: Panorama | F5: Wita | G5: Rotama
A6: Shopping
A7: Compulsory shop stops | B7: Ginseng & Cosmetic · Red Pine & DFS · Grocery market | C7: Ginseng · Cosmetic · Red Pine · DFS · Lotte Premium Outlet · Cookies | D7: Ginseng · Cosmetic · DFS · Red Pine & Amethyst · Grocery | E7: Ginseng & Cosmetic · Red Pine & DFS | F7: Ginseng · Cosmetic · Red Pine · DFS | G7: Ginseng · Cosmetic · Red Pine · DFS
A8: Number of shop stops | B8: 5 | C8: 6 | D8: 5 | E8: 4 | F8: 4 | G8: 4
A9: Fine for skipping a shop | D9: 1000000 | F9: 3000000 | G9: 4000000
A10: Booking terms
A11: Minimum group size | B11: 20 | C11: 20 adults | D11: 20 adults | E11: 20 adults | F11: 20 adults | G11: 20
A12: Non-refundable deposit | B12: IDR 13 M + visa | C12: Not legible | D12: IDR 8 M (high season, Asia) | E12: Not stated | F12: IDR 10 M (tour < 30 M) | G12: IDR 10 M (tour < 30 M)
A13: Final payment due | B13: 1 month before | C13: Not legible | D13: 30 days before | E13: Not stated | F13: 21 days (low) / 30 days (peak) before | G13: 21 days (low) / 30 days (peak) before
A14: Cancellation charges | B14: Deposit forfeited | C14: Not legible | D14: 50% at 45–30 days · 75% at 30–20 · 100% ≤19 | E14: Not stated | F14: 80% at 45–30 working days · 100% ≤29 | G14: 80% at 45–30 working days · 100% ≤29
A15: Included extras
A16: Bonuses | B16: Group travel insurance | C16: Travel SIM · free cabin suitcase · insurance | D16: Travel SIM · water · Jakarta airport handling · free group visa | E16: Mineral water | F16: Insurance · Lotte World (entry implied, confirm) | G16: Free group visa · insurance
A17: Tour leader from Jakarta | B17: Yes | C17: Yes | D17: Yes | E17: Not stated | F17: Yes | G17: Yes
A19: Wita and Rotama brochures share the same office footer and word-for-word terms, so they look like the same company group.

Sheet Sightseeing
A1: Sightseeing: What Each Tour Visits
A2: Facts only. ✓ = included (counted) · Photo stop = drive-by or photo only · – = not included. See 'Sightseeing Opinion' for the subjective view.
A5: Attraction / experience | B5: Aviatour | C5: Bayu Buana | D5: Obaja | E5: Panorama | F5: Wita | G5: Rotama
A6: Busan
A7: Gamcheon Culture Village | B7: ✓ | C7: ✓ | D7: ✓ | E7: ✓ | F7: ✓ | G7: –
A8: BIFF Street / Square | B8: ✓ | C8: ✓ | D8: ✓ | E8: ✓ | F8: ✓ | G8: –
A9: Haedong Yonggungsa Temple | B9: ✓ | C9: – | D9: ✓ | E9: ✓ | F9: ✓ | G9: –
A10: Haeundae Sky Capsule Train | B10: ✓ (or Beach Train) | C10: ✓ | D10: – | E10: ✓ | F10: – | G10: –
A11: Haeundae Beach & The Bay 101 | B11: – | C11: – | D11: – | E11: – | F11: ✓ | G11: –
A12: Cheongsapo Station | B12: ✓ | C12: – | D12: – | E12: – | F12: – | G12: –
A13: Oryukdo Skywalk | B13: – | C13: ✓ | D13: – | E13: – | F13: ✓ | G13: –
A14: Jagalchi Fish Market | B14: – | C14: ✓ | D14: – | E14: – | F14: ✓ | G14: –
A15: Gwangandaegyo Bridge | B15: – | C15: – | D15: – | E15: Photo stop | F15: – | G15: –
A16: Spring flowers
A17: Jinhae cherry blossom | B17: – | C17: ✓ (8 Apr) | D17: – | E17: – | F17: ✓ (28 Mar) | G17: –
A18: Yeouido cherry blossom (Seoul) | B18: ✓ | C18: – | D18: – | E18: – | F18: – | G18: –
A19: Maehwa (plum) Village | B19: – | C19: – | D19: – | E19: ✓ | F19: – | G19: –
A20: Gurye Sansuyu Village | B20: – | C20: – | D20: – | E20: ✓ | F20: – | G20: –
A21: Jeonju & countryside
A22: Jeonju Hanok Village | B22: ✓ | C22: – | D22: – | E22: ✓ + overnight | F22: – | G22: –
A23: Gyeonggijeon Shrine | B23: ✓ | C23: – | D23: – | E23: – | F23: – | G23: –
A24: Jeonju Cathedral | B24: Photo stop | C24: – | D24: – | E24: Photo stop | F24: – | G24: –
A25: Jaman Mural Village | B25: ✓ | C25: – | D25: – | E25: – | F25: – | G25: –
A26: Nami Island | B26: – | C26: ✓ | D26: ✓ | E26: – | F26: – | G26: –
A27: Strawberry picking | B27: – | C27: – | D27: – | E27: ✓ | F27: – | G27: –
A28: Seoul & Incheon
A29: Gyeongbokgung Palace | B29: ✓ | C29: ✓ in hanbok | D29: ✓ in hanbok | E29: ✓ | F29: ✓ in hanbok | G29: ✓
A30: The Blue House | B30: Photo stop | C30: – | D30: – | E30: – | F30: Photo stop | G30: –
A31: Gwanghwamun Square | B31: – | C31: – | D31: – | E31: – | F31: ✓ | G31: –
A32: Gwangjang Market | B32: – | C32: – | D32: – | E32: – | F32: ✓ | G32: –
A33: Eunpyeong Hanok Village | B33: – | C33: – | D33: – | E33: – | F33: ✓ | G33: –
A34: National Folk Museum | B34: – | C34: – | D34: – | E34: – | F34: – | G34: ✓
A35: Starfield Library (COEX) | B35: ✓ | C35: ✓ | D35: – | E35: ✓ | F35: ✓ | G35: ✓
A36: Lotte World | B36: – | C36: – | D36: – | E36: – | F36: ✓ | G36: –
A37: N Seoul Tower | B37: ✓ cable car (outside view) | C37: – | D37: – | E37: ✓ cable car | F37: – | G37: ✓
A38: Love Lock area | B38: ✓ | C38: – | D38: – | E38: ✓ | F38: – | G38: ✓
A39: Han River Park | B39: (see Yeouido) | C39: ✓ | D39: – | E39: – | F39: – | G39: ✓
A40: Myeongdong | B40: ✓ | C40: ✓ | D40: ✓ | E40: ✓ | F40: ✓ | G40: ✓
... A47: Inspire Aurora Square | B47: – | C47: – | D47: – | E47: – | F47: – | G47: ✓
A48: Hands-on experiences
...

Sheet Sightseeing Opinion
A1: Sightseeing: Subjective View
A2: Opinion, not fact. Scores are out of 5. Change any blue score and the stars, averages and ranking update.
A5: Criterion | B5: Aviatour | C5: Bayu Buana | D5: Obaja | E5: Panorama | F5: Wita | G5: Rotama
A6: Scores (1–5)
A7: Variety of sights | B7: 5 | C7: 4 | D7: 2 | E7: 5 | F7: 4 | G7: 3
A8: Cherry blossom chance | B8: 4 | C8: 3 | D8: 1 | E8: 1 | F8: 5 | G8: 0
A9: Culture & tradition | B9: 5 | C9: 3 | D9: 3 | E9: 5 | F9: 4 | G9: 3
A10: Nature & scenery | B10: 4 | C10: 4 | D10: 3 | E10: 5 | F10: 4 | G10: 2
A11: Hands-on / fun | B11: 3 | C11: 5 | D11: 2 | E11: 4 | F11: 4 | G11: 3
A12: Low shopping pressure | B12: 3 | C12: 2 | D12: 2 | E12: 4 | F12: 3 | G12: 3
A13: Uniqueness of itinerary | B13: 3 | C13: 4 | D13: 2 | E13: 5 | F13: 4 | G13: 3
A14: AVERAGE SCORE | B14: =AVERAGE(B7:B13) -> 3.8571429 | C14: =AVERAGE(C7:C13) -> 3.5714286 | D14: =AVERAGE(D7:D13) -> 2.1428571 | E14: =AVERAGE(E7:E13) -> 4.1428571 | F14: =AVERAGE(F7:F13) -> 4 | G14: =AVERAGE(G7:G13) -> 2.4285714
A15: Rank (1 = best) | B15: =RANK(B14,$B$14:$G$14,0) -> 3 | C15: =RANK(C14,$B$14:$G$14,0) -> 4 | D15: =RANK(D14,$B$14:$G$14,0) -> 6 | E15: =RANK(E14,$B$14:$G$14,0) -> 1 | F15: =RANK(F14,$B$14:$G$14,0) -> 2 | G15: =RANK(G14,$B$14:$G$14,0) -> 5
A16: As stars
A17: Variety of sights | B17: =REPT("★",B7)&REPT("☆",5-B7) -> ★★★★★ | C17: =REPT("★",C7)&REPT("☆",5-C7) -> ★★★★☆ | D17: =REPT("★",D7)&REPT("☆",5-D7) -> ★★☆☆☆ | E17: =REPT("★",E7)&REPT("☆",5-E7) -> ★★★★★ | F17: =REPT("★",F7)&REPT("☆",5-F7) -> ★★★★☆ | G17: =REPT("★",G7)&REPT("☆",5-G7) -> ★★★☆☆
A18: Cherry blossom chance | B18: =REPT("★",B8)&REPT("☆",5-B8) -> ★★★★☆ | C18: =REPT("★",C8)&REPT("☆",5-C8) -> ★★★☆☆ | D18: =REPT("★",D8)&REPT("☆",5-D8) -> ★☆☆☆☆ | E18: =REPT("★",E8)&REPT("☆",5-E8) -> ★☆☆☆☆ | F18: =REPT("★",F8)&REPT("☆",5-F8) -> ★★★★★ | G18: =REPT("★",G8)&REPT("☆",5-G8) -> ☆☆☆☆☆
A19: Culture & tradition | B19: =REPT("★",B9)&REPT("☆",5-B9) -> ★★★★★ | C19: =REPT("★",C9)&REPT("☆",5-C9) -> ★★★☆☆ | D19: =REPT("★",D9)&REPT("☆",5-D9) -> ★★★☆☆ | E19: =REPT("★",E9)&REPT("☆",5-E9) -> ★★★★★ | F19: =REPT("★",F9)&REPT("☆",5-F9) -> ★★★★☆ | G19: =REPT("★",G9)&REPT("☆",5-G9) -> ★★★☆☆
A20: Nature & scenery | B20: =REPT("★",B10)&REPT("☆",5-B10) -> ★★★★☆ | C20: =REPT("★",C10)&REPT("☆",5-C10) -> ★★★★☆ | D20: =REPT("★",D10)&REPT("☆",5-D10) -> ★★★☆☆ | E20: =REPT("★",E10)&REPT("☆",5-E10) -> ★★★★★ | F20: =REPT("★",F10)&REPT("☆",5-F10) -> ★★★★☆ | G20: =REPT("★",G10)&REPT("☆",5-G10) -> ★★☆☆☆
A21: Hands-on / fun | B21: =REPT("★",B11)&REPT("☆",5-B11) -> ★★★☆☆ | C21: =REPT("★",C11)&REPT("☆",5-C11) -> ★★★★★ | D21: =REPT("★",D11)&REPT("☆",5-D11) -> ★★☆☆☆ | E21: =REPT("★",E11)&REPT("☆",5-E11) -> ★★★★☆ | F21: =REPT("★",F11)&REPT("☆",5-F11) -> ★★★★☆ | G21: =REPT("★",G11)&REPT("☆",5-G11) -> ★★★☆☆
A22: Low shopping pressure | B22: =REPT("★",B12)&REPT("☆",5-B12) -> ★★★☆☆ | C22: =REPT("★",C12)&REPT("☆",5-C12) -> ★★☆☆☆ | D22: =REPT("★",D12)&REPT("☆",5-D12) -> ★★☆☆☆ | E22: =REPT("★",E12)&REPT("☆",5-E12) -> ★★★★☆ | F22: =REPT("★",F12)&REPT("☆",5-F12) -> ★★★☆☆ | G22: =REPT("★",G12)&REPT("☆",5-G12) -> ★★★☆☆
A23: Uniqueness of itinerary | B23: =REPT("★",B13)&REPT("☆",5-B13) -> ★★★☆☆ | C23: =REPT("★",C13)&REPT("☆",5-C13) -> ★★★★☆ | D23: =REPT("★",D13)&REPT("☆",5-D13) -> ★★☆☆☆ | E23: =REPT("★",E13)&REPT("☆",5-E13) -> ★★★★★ | F23: =REPT("★",F13)&REPT("☆",5-F13) -> ★★★★☆ | G23: =REPT("★",G13)&REPT("☆",5-G13) -> ★★★☆☆
A24: In a nutshell
A25: Feels like | B25: A well-paced "best of Korea" sampler | C25: A romantic spring trip with plenty of retail time | D25: A no-frills sampler: price comes first | E25: A slower, experiential spring trip out of the cities | F25: A comfortable, Busan-focused cherry blossom trip with a playful Seoul end | G25: A quick Seoul getaway, not a full Korea tour
A26: Strengths | B26: Coastal Busan, a full Jeonju day, Yeouido blossoms, Namsan cable car, Hongdae | C26: Jinhae, Oryukdo Skywalk, Jagalchi, Nami Island, hanbok at Gyeongbok, 3 food activities | D26: Must-sees at the lowest price; a free day | E26: Plum & sansuyu villages, hanok overnight, strawberries, N Seoul Tower, fewest shops | F26: Best-timed Jinhae, fullest Busan, Gwangjang Market, Eunpyeong Hanok, Lotte World | G26: Aurora Square, Fairy Tale Village, Folk Museum, direct flights
A27: Weaknesses | B27: KTX transfer right after the overnight flight; tower outside view only | C27: Heaviest shopping; no Jeonju or N Seoul Tower; Jinhae timing late | D27: Thinnest programme (~9 sights); no blossoms; hotel in Anyang | E27: No cherry blossom; busy first Busan day; floor bedding in Jeonju | F27: No Nami, Jeonju or N Seoul Tower; Lotte World takes most of a day | G27: No Busan or countryside; cold November; different product

Sheet Notes
A1: Notes & Assumptions
A2: Inputs the price formulas depend on. Change a blue value and every sheet updates.
A5: Assumption | B5: Value | C5: Source / reason
A6: USD → IDR exchange rate | B6: 16500 | C6: Assumption for converting USD tipping (Obaja USD 50, Panorama USD 56). Check the current rate.
A7: Aviatour tipping estimate (IDR) | B7: 950000 | C7: Aviatour's brochure does not quote tipping. Estimated at the level other operators charge (IDR 0.9–1.0 M). Ask Aviatour.
A8: Obaja PPN rate | B8: 0.011 | C8: Obaja lists PPN as excluded without a rate. Assumed 1.1%, the rate every other operator uses.
A10: Legend
A11: Blue numbers | B11: Figures typed in from the brochures (inputs).
A12: Black numbers | B12: Formulas: totals, all-in prices, per-day ratios, counts.
A13: Yellow cells | B13: Assumptions on this sheet: change them to re-run the comparison.
A14: Green → red shading | B14: Better → worse within a row (cheaper / more meals / more sights is greener).
A15: Cell comments (red corner) | B15: Extra detail from the brochure, e.g. hotel notes or handwritten agent quotes.
A17: Sources & caveats
A18: • Six scanned brochures from Aviatour, Bayu Buana, Obaja, Panorama JTB, Wita (Leisure Holiday) and Rotama; full transcriptions are in the itineraries/ folder.
A19: • Handwritten all-in quotes by the agents (Bayu Buana, Panorama, Wita, Rotama) are shown on the Price sheet as a cross-check against the calculated all-in. Confirm them in writing.
A20: • Bayu Buana page 3 (inclusions, exclusions, 07 Apr prices) was too blurred to read. Its handwritten quote is ambiguous; only Rp 28.58 M fits the printed prices.
A21: • Wita's inclusions list says CGK-ICN-CGK but the itinerary flies into Busan; Lotte World entry is implied but not stated. Wita's year is not printed (presumed 2027).
A22: • Bloom dates vary every year; season notes describe typical windows only.
